{"name": "test_fixture", "status": "broken", "statusDetails": {"message": "TypeError: 'TestExample' object is not callable", "trace": "a_change = <mock_test.TestExample object at 0x0000025970497BE0>\n\n    @pytest.mark.test02\n    @pytest.mark.repeat(1)\n    @allure.story(\"测试1\")\n    def test_fixture(a_change):\n>       a_change().strip()\nE       TypeError: 'TestExample' object is not callable\n\nmock_test.py:64: TypeError"}, "start": 1643100387154, "stop": 1643100387155, "uuid": "c50091e9-0269-480e-9def-ca5de8638d41", "historyId": "0de6bc0bb13e29ad036c8e8d962b2ab9", "testCaseId": "6050fc196d18216156e52eddaff4a272", "fullName": "mock_test.TestExample#test_fixture", "labels": [{"name": "story", "value": "测试1"}, {"name": "feature", "value": "测试样例1"}, {"name": "tag", "value": "test02"}, {"name": "tag", "value": "repeat(1)"}, {"name": "suite", "value": "mock_test"}, {"name": "subSuite", "value": "TestExample"}, {"name": "host", "value": "Ruix"}, {"name": "thread", "value": "14884-MainThread"}, {"name": "framework", "value": "pytest"}, {"name": "language", "value": "cpython3"}, {"name": "package", "value": "mock_test"}]}